{"uuid": "4f182b1b-02ac-4207-929e-8f35641bea6b", "children": ["9d4d938c-d828-4a03-b279-5935cee00055"], "befores": [{"name": "setup", "status": "broken", "statusDetails": {"message": "urllib3.exceptions.ProtocolError: ('Connection aborted.', ConnectionResetError(10054, 'An existing connection was forcibly closed by the remote host', None, 10054, None))\n", "trace": "  File \"E:\\New folder\\python_selenium\\venv\\lib\\site-packages\\pluggy\\_callers.py\", line 80, in _multicall\n    res = hook_impl.function(*args)\n  File \"E:\\New folder\\python_selenium\\venv\\lib\\site-packages\\_pytest\\fixtures.py\", line 1123, in pytest_fixture_setup\n    result = call_fixture_func(fixturefunc, request, kwargs)\n  File \"E:\\New folder\\python_selenium\\venv\\lib\\site-packages\\_pytest\\fixtures.py\", line 895, in call_fixture_func\n    fixture_result = next(generator)\n  File \"E:\\New folder\\python_selenium\\tests\\conftest.py\", line 58, in setup\n    driver.get(PropertyLoader.getUnitedStatesUrl())\n  File \"E:\\New folder\\python_selenium\\venv\\lib\\site-packages\\selenium\\webdriver\\remote\\webdriver.py\", line 442, in get\n    self.execute(Command.GET, {'url': url})\n  File \"E:\\New folder\\python_selenium\\venv\\lib\\site-packages\\selenium\\webdriver\\remote\\webdriver.py\", line 428, in execute\n    response = self.command_executor.execute(driver_command, params)\n  File \"E:\\New folder\\python_selenium\\venv\\lib\\site-packages\\selenium\\webdriver\\remote\\remote_connection.py\", line 347, in execute\n    return self._request(command_info[0], url, body=data)\n  File \"E:\\New folder\\python_selenium\\venv\\lib\\site-packages\\selenium\\webdriver\\remote\\remote_connection.py\", line 369, in _request\n    response = self._conn.request(method, url, body=body, headers=headers)\n  File \"E:\\New folder\\python_selenium\\venv\\lib\\site-packages\\urllib3\\request.py\", line 78, in request\n    return self.request_encode_body(\n  File \"E:\\New folder\\python_selenium\\venv\\lib\\site-packages\\urllib3\\request.py\", line 170, in request_encode_body\n    return self.urlopen(method, url, **extra_kw)\n  File \"E:\\New folder\\python_selenium\\venv\\lib\\site-packages\\urllib3\\poolmanager.py\", line 376, in urlopen\n    response = conn.urlopen(method, u.request_uri, **kw)\n  File \"E:\\New folder\\python_selenium\\venv\\lib\\site-packages\\urllib3\\connectionpool.py\", line 798, in urlopen\n    retries = retries.increment(\n  File \"E:\\New folder\\python_selenium\\venv\\lib\\site-packages\\urllib3\\util\\retry.py\", line 550, in increment\n    raise six.reraise(type(error), error, _stacktrace)\n  File \"E:\\New folder\\python_selenium\\venv\\lib\\site-packages\\urllib3\\packages\\six.py\", line 769, in reraise\n    raise value.with_traceback(tb)\n  File \"E:\\New folder\\python_selenium\\venv\\lib\\site-packages\\urllib3\\connectionpool.py\", line 714, in urlopen\n    httplib_response = self._make_request(\n  File \"E:\\New folder\\python_selenium\\venv\\lib\\site-packages\\urllib3\\connectionpool.py\", line 466, in _make_request\n    six.raise_from(e, None)\n  File \"<string>\", line 3, in raise_from\n  File \"E:\\New folder\\python_selenium\\venv\\lib\\site-packages\\urllib3\\connectionpool.py\", line 461, in _make_request\n    httplib_response = conn.getresponse()\n  File \"C:\\Users\\DELL\\AppData\\Local\\Programs\\Python\\Python39\\lib\\http\\client.py\", line 1347, in getresponse\n    response.begin()\n  File \"C:\\Users\\DELL\\AppData\\Local\\Programs\\Python\\Python39\\lib\\http\\client.py\", line 307, in begin\n    version, status, reason = self._read_status()\n  File \"C:\\Users\\DELL\\AppData\\Local\\Programs\\Python\\Python39\\lib\\http\\client.py\", line 268, in _read_status\n    line = str(self.fp.readline(_MAXLINE + 1), \"iso-8859-1\")\n  File \"C:\\Users\\DELL\\AppData\\Local\\Programs\\Python\\Python39\\lib\\socket.py\", line 704, in readinto\n    return self._sock.recv_into(b)\n"}, "start": 1692691858128, "stop": 1692691869447}], "start": 1692691858128, "stop": 1692691874173}